<?xml version="1.0" ?>
<!-- =================================================================================== -->
<!-- |    This document was autogenerated by xacro from seven_dof_arm.xacro            | -->
<!-- |    EDITING THIS FILE BY HAND IS NOT RECOMMENDED                                 | -->
<!-- =================================================================================== -->
<!--Defining Robot-->
<robot name="seven_dof_arm" xmlns:xacro="http://www.ros.org/wiki/xacro">
  <!--//////////////////////////////////////////////////////////////////////////////////////////////////////////////////////////////////-->
  <!--Defining Materials-->
  <!--Black Material-->
  <material name="black">
    <color rgba="0 0 0 1"/>
  </material>
  <!--White Material-->
  <material name="white">
    <color rgba="1 1 1 1"/>
  </material>
  <!--Red Material-->
  <material name="red">
    <color rgba="0.8 0 0 1"/>
  </material>
  <!--/////////////////////////////////////////////////////__Bottom Fixed Link__////////////////////////////////////////////////////////////////////-->
  <link name="bottom_link">
    <!--Visualisation of robot-->
    <visual>
      <!--Origin-->
      <origin rpy="0 0 0" xyz="0 0 -0.04"/>
      <!--Geometry-->
      <geometry>
        <!--Box-->
        <box size="1 1 0.02"/>
      </geometry>
      <!--Material-->
      <material name="brown"/>
    </visual>
    <!--Collision-->
    <collision>
      <!--Origin-->
      <origin rpy="0 0 0" xyz="0 0 -0.04"/>
      <!--Geometry-->
      <geometry>
        <box size="1 1 0.02"/>
      </geometry>
    </collision>
  </link>
  <!--Adding Gazebo reference-->
  <gazebo reference="bottom_link">
    <material>Gazebo/White</material>
  </gazebo>
  <joint name="bottom_joint" type="fixed">
    <!--Origin-->
    <origin rpy="0 0 0" xyz="0 0 0"/>
    <!--Parent Link-->
    <parent link="base_link"/>
    <!--Child Link-->
    <child link="bottom_link"/>
  </joint>
  <!--/////////////////////////////////////////////////////__Base Link__////////////////////////////////////////////////////////////////////-->
  <link name="base_link">
    <!--Visualization-->
    <visual>
      <origin rpy="1.570795 0 0" xyz="0 0 0"/>
      <!--Rotating pi2-->
      <geometry>
        <box size="0.1 0.1 0.1"/>
      </geometry>
      <material name="white"/>
    </visual>
    <!--Collision-->
    <collision>
      <origin rpy="1.570795 0 0" xyz="0 0 0"/>
      <!--Rotating pi2-->
      <geometry>
        <box size="0.1 0.1 0.1"/>
      </geometry>
    </collision>
    <inertial>
      <mass value="1"/>
      <inertia ixx="1.0" ixy="0.0" ixz="0.0" iyy="1.0" iyz="0.0" izz="1.0"/>
    </inertial>
  </link>
  <!--Gazebo Reference-->
  <gazebo reference="base_link">
    <material>Gazebo/White</material>
  </gazebo>
  <!--Joint-->
  <joint name="shoulder_pan_joint" type="revolute">
    <origin rpy="0 1.570795 0.0" xyz="0 0 0.05"/>
    <axis xyz="-1 0 0"/>
    <parent link="base_link"/>
    <child link="shoulder_pan_link"/>
    <limit effort="300" lower="-2.61799387799" upper="1.98967534727" velocity="1"/>
    <dynamics damping="50" friction="1"/>
  </joint>
  <!--/////////////////////////////////////////////////////__Shoulder Pan Link__////////////////////////////////////////////////////////////////////-->
  <link name="shoulder_pan_link">
    <visual>
      <origin rpy="0 1.570795 0" xyz="0 0 0"/>
      <geometry>
        <cylinder length="0.08" radius="0.04"/>
      </geometry>
      <material name="red"/>
    </visual>
    <collision>
      <origin rpy="0 1.570795 0" xyz="0 0 0"/>
      <geometry>
        <cylinder length="0.08" radius="0.04"/>
      </geometry>
    </collision>
    <inertial>
      <mass value="1"/>
      <inertia ixx="1.0" ixy="0.0" ixz="0.0" iyy="1.0" iyz="0.0" izz="1.0"/>
    </inertial>
  </link>
  <!--Gazebo Reference-->
  <gazebo reference="shoulder_pan_link">
    <material>Gazebo/Red</material>
  </gazebo>
  <!--Joint-->
  <joint name="shoulder_pitch_joint" type="revolute">
    <origin rpy="-1.570795 0 1.570795" xyz="-0.041 0.0021 0"/>
    <axis xyz="1 0 0"/>
    <parent link="shoulder_pan_link"/>
    <child link="shoulder_pitch_link"/>
    <limit effort="300" lower="-1.16937059884" upper="1.90240888467" velocity="1"/>
    <dynamics dmaping="50" friction="1"/>
  </joint>
  <!--/////////////////////////////////////////////////////__Shoulder Pitch Link__////////////////////////////////////////////////////////////////////-->
  <link name="shoulder_pitch_link">
    <visual>
      <origin rpy="0 1.570795 0" xyz="-0.002 0 0.04"/>
      <geometry>
        <box size="0.14 0.04 0.04"/>
      </geometry>
      <material name="white"/>
    </visual>
    <collision>
      <origin rpy="0 1.570795 0" xyz="-0.002 0 0.04"/>
      <geometry>
        <box size="0.14 0.04 0.04"/>
      </geometry>
    </collision>
    <inertial>
      <mass value="1"/>
      <inertia ixx="1.0" ixy="0.0" ixz="0.0" iyy="1.0" iyz="0.0" izz="1.0"/>
    </inertial>
  </link>
  <!--Gazebo Reference-->
  <gazebo reference="shoulder_pitch_link">
    <material>Gazebo/White</material>
  </gazebo>
  <!--Joint-->
  <joint name="elbow_roll_joint" type="revolute">
    <origin rpy="3.14159 0 1.570795" xyz="-0.002 0 0.1206"/>
    <axis xyz="-1 0 0"/>
    <parent link="shoulder_pitch_link"/>
    <child link="elbow_roll_link"/>
    <limit effort="300" lower="-2.61799387799" upper="0.715584993318" velocity="1"/>
    <dynamics dmaping="50" friction="1"/>
  </joint>
  <!--/////////////////////////////////////////////////////__Elbow Roll Link__////////////////////////////////////////////////////////////////////-->
  <link name="elbow_roll_link">
    <visual>
      <origin rpy="0 1.570795 0" xyz="-0.015 0 -0"/>
      <geometry>
        <cylinder length="0.06" radius="0.02"/>
      </geometry>
      <material name="black"/>
    </visual>
    <collision>
      <origin rpy="0 1.570795 0" xyz="-0.015 0 -0"/>
      <geometry>
        <cylinder length="0.06" radius="0.02"/>
      </geometry>
    </collision>
    <inertial>
      <mass value="1"/>
      <inertia ixx="1.0" ixy="0.0" ixz="0.0" iyy="1.0" iyz="0.0" izz="1.0"/>
    </inertial>
  </link>
  <!--Gazebo Reference-->
  <gazebo reference="elbow_roll_link">
    <material>Gazebo/Black</material>
  </gazebo>
  <!--Joint-->
  <joint name="elbow_pitch_joint" type="revolute">
    <origin rpy="0.055 1.570795 0" xyz="-0.035 0 0"/>
    <axis xyz="1 0 0"/>
    <parent link="elbow_roll_link"/>
    <child link="elbow_pitch_link"/>
    <limit effort="300" lower="-1.60570291183" upper="1.91986217719" velocity="1"/>
    <dynamics dmaping="50" friction="1"/>
  </joint>
  <!--/////////////////////////////////////////////////////__Elbow Pitch Link__////////////////////////////////////////////////////////////////////-->
  <link name="elbow_pitch_link">
    <visual>
      <origin rpy="0 1.570795 0" xyz="0 0 -0.12"/>
      <geometry>
        <box size="0.22 0.04 0.04"/>
      </geometry>
      <material name="red"/>
    </visual>
    <collision>
      <origin rpy="0 1.570795 0" xyz="0 0 -0.12"/>
      <geometry>
        <box size="0.22 0.04 0.04"/>
      </geometry>
    </collision>
    <inertial>
      <mass value="1"/>
      <inertia ixx="1.0" ixy="0.0" ixz="0.0" iyy="1.0" iyz="0.0" izz="1.0"/>
    </inertial>
  </link>
  <!--Gazebo Reference-->
  <gazebo reference="elbow_pitch_link">
    <material>Gazebo/Red</material>
  </gazebo>
  <!--Joint-->
  <joint name="wrist_roll_joint" type="revolute">
    <origin rpy="0 1.570795 3.14159" xyz="0 0.0081 -0.248"/>
    <axis xyz="1 0 0"/>
    <parent link="elbow_pitch_link"/>
    <child link="wrist_roll_link"/>
    <limit effort="300" lower="-2.61799387799" upper="2.61799387799" velocity="1"/>
    <dynamics dmaping="50" friction="1"/>
  </joint>
  <!--/////////////////////////////////////////////////////__Wrist Roll Link__////////////////////////////////////////////////////////////////////-->
  <link name="wrist_roll_link">
    <visual>
      <origin rpy="0 1.570795 0" xyz="0 0 0"/>
      <geometry>
        <cylinder length="0.04" radius="0.02"/>
      </geometry>
      <material name="black"/>
    </visual>
    <collision>
      <origin rpy="0 1.570795 0" xyz="0 0 0"/>
      <geometry>
        <cylinder length="0.04" radius="0.02"/>
      </geometry>
    </collision>
    <inertial>
      <mass value="1"/>
      <inertia ixx="1.0" ixy="0.0" ixz="0.0" iyy="1.0" iyz="0.0" izz="1.0"/>
    </inertial>
  </link>
  <!--Gazebo Reference-->
  <gazebo reference="wrist_roll_link">
    <material>Gazebo/Black</material>
  </gazebo>
  <!--Joint-->
  <joint name="wrist_pitch_joint" type="revolute">
    <origin rpy="0 1.570795 0" xyz="0 0 0.0001"/>
    <axis xyz="1 0 0"/>
    <parent link="wrist_roll_link"/>
    <child link="wrist_pitch_link"/>
    <limit effort="300" lower="1.60570291183" upper="1.97222205475" velocity="1"/>
    <dynamics dmaping="50" friction="1"/>
  </joint>
  <!--/////////////////////////////////////////////////////__Wrist Pitch Link__////////////////////////////////////////////////////////////////////-->
  <link name="wrist_pitch_link">
    <visual>
      <origin rpy="0 1.570795 0" xyz="0 0 0.04"/>
      <geometry>
        <box size="0.06 0.04 0.04"/>
      </geometry>
      <material name="white"/>
    </visual>
    <collision>
      <origin rpy="0 1.570795 0" xyz="0 0 0.04"/>
      <geometry>
        <box size="0.06 0.04 0.04"/>
      </geometry>
    </collision>
    <inertial>
      <mass value="1"/>
      <inertia ixx="1.0" ixy="0.0" ixz="0.0" iyy="1.0" iyz="0.0" izz="1.0"/>
    </inertial>
  </link>
  <!--Gazebo Reference-->
  <gazebo reference="wrist_pitch_link">
    <material>Gazebo/White</material>
  </gazebo>
  <!--Joint-->
  <joint name="gripper_roll_joint" type="revolute">
    <origin rpy="4.712385 -1.570795 0" xyz="0 0 0.08"/>
    <axis xyz="1 0 0"/>
    <parent link="wrist_pitch_link"/>
    <child link="gripper_roll_link"/>
    <limit effort="300" lower="-2.61799387799" upper="2.61799387799" velocity="1"/>
    <dynamics dmaping="50" friction="1"/>
  </joint>
  <!--/////////////////////////////////////////////////////__Gripper Roll Link__////////////////////////////////////////////////////////////////////-->
  <link name="gripper_roll_link">
    <visual>
      <origin rpy="0 1.570795 0" xyz="0 0 0"/>
      <geometry>
        <cylinder length="0.02" radius="0.04"/>
      </geometry>
      <material name="red"/>
    </visual>
    <collision>
      <origin rpy="0 1.570795 0" xyz="0 0 0"/>
      <geometry>
        <cylinder length="0.02" radius="0.04"/>
      </geometry>
    </collision>
    <inertial>
      <mass value="1"/>
      <inertia ixx="1.0" ixy="0.0" ixz="0.0" iyy="1.0" iyz="0.0" izz="1.0"/>
    </inertial>
  </link>
  <!--Gazebo Reference-->
  <gazebo reference="gripper_roll_link">
    <material>Gazebo/Red</material>
  </gazebo>
  <!--Joint-->
  <joint name="finger_joint1" type="prismatic">
    <origin xyz="0 0 0"/>
    <axis xyz="0 1 0"/>
    <parent link="gripper_roll_link"/>
    <child link="gripper_final_link1"/>
    <limit effort="100" lower="0" upper="0.03" velocity="1"/>
    <!--Safety Controller-->
    <safety_controller k_position="20" k_velocity="20" soft_lower_limit="-0.15" soft_upper_limit="0.0"/>
    <dynamics dmaping="50" friction="1"/>
  </joint>
  <!--/////////////////////////////////////////////////////__Left Gripper AFT Link__////////////////////////////////////////////////////////////////////-->
  <link name="gripper_final_link1">
    <visual>
      <origin xyz="0.04 -0.03 0"/>
      <geometry>
        <box size="0.08 0.01 0.01"/>
      </geometry>
      <material name="white"/>
    </visual>
    <inertial>
      <mass value="1"/>
      <inertia ixx="1.0" ixy="0.0" ixz="0.0" iyy="1.0" iyz="0.0" izz="1.0"/>
    </inertial>
  </link>
  <!--Gazebo Reference-->
  <gazebo reference="l_gripper_aft_link">
    <material>Gazebo/White</material>
  </gazebo>
  <!--Joint-->
  <joint name="finger_joint2" type="prismatic">
    <origin xyz="0 0 0"/>
    <axis xyz="0 1 0"/>
    <parent link="gripper_roll_link"/>
    <child link="gripper_final_link2"/>
    <limit effort="1" lower="-0.03" upper="0" velocity="1"/>
    <dynamics dmaping="50" friction="1"/>
  </joint>
  <!--/////////////////////////////////////////////////////__Right Gripper AFT Link__////////////////////////////////////////////////////////////////////-->
  <link name="gripper_final_link2">
    <visual>
      <origin xyz="0.04 0.03 0"/>
      <geometry>
        <box size="0.08 0.01 0.01"/>
      </geometry>
      <material name="white"/>
    </visual>
    <inertial>
      <mass value="1"/>
      <inertia ixx="1.0" ixy="0.0" ixz="0.0" iyy="1.0" iyz="0.0" izz="1.0"/>
    </inertial>
  </link>
  <!--Gazebo Reference-->
  <gazebo reference="r_gripper_aft_link">
    <material>Gazebo/White</material>
  </gazebo>
  <!--/////////////////////////////////////////////////////__Grasping Frame__////////////////////////////////////////////////////////////////////-->
  <link name="grasping_frame">
    <inertial>
      <origin rpy="0 0 0" xyz="0 0 0"/>
      <mass value="0.0001"/>
      <cuboid_inertia mass="0.0001" x="0.0001" y="0.0001" z="0.0001"/>
      <inertia ixx="1.0" ixy="0.0" ixz="0.0" iyy="100.0" iyz="0.0" izz="0.0"/>
    </inertial>
    <visual>
      <origin xyz="0 0 0"/>
      <geometry>
        <box size="0.02 0.02 0.02"/>
      </geometry>
      <material name="white"/>
    </visual>
    <inertial>
      <mass value="1"/>
      <inertia ixx="1.0" ixy="0.0" ixz="0.0" iyy="1.0" iyz="0.0" izz="1.0"/>
    </inertial>
  </link>
  <!--Joint-->
  <joint name="grasping_frame_joint" type="fixed">
    <origin rpy="0 0 0" xyz="0.08 0 0"/>
    <parent link="gripper_roll_link"/>
    <child link="grasping_frame"/>
  </joint>
  <!-- including another file
	<xacro:include filename="$(find seven_dof_arm)/urdf/sensors/xtion_pro_live.urdf.xacro"/>-->
  <transmission name="t1">
    <!--Type of Transmission-->
    <type>transmission_interace/SimpleTransmission</type>
    <!--Joint for transmission-->
    <joint name="shoulder_pan_joint">
      <hardwareInterface>PositionJointInterface</hardwareInterface>
    </joint>
    <!--Actuator-->
    <actuator name="motor1">
      <hardwareInterface>PositionJointInterface</hardwareInterface>
      <mechanicalReduction>1</mechanicalReduction>
    </actuator>
  </transmission>
  <transmission name="t1">
    <!--Type of Transmission-->
    <type>transmission_interace/SimpleTransmission</type>
    <!--Joint for transmission-->
    <joint name="shoulder_pitch_joint">
      <hardwareInterface>PositionJointInterface</hardwareInterface>
    </joint>
    <!--Actuator-->
    <actuator name="motor1">
      <hardwareInterface>PositionJointInterface</hardwareInterface>
      <mechanicalReduction>1</mechanicalReduction>
    </actuator>
  </transmission>
  <transmission name="t1">
    <!--Type of Transmission-->
    <type>transmission_interace/SimpleTransmission</type>
    <!--Joint for transmission-->
    <joint name="elbow_roll_joint">
      <hardwareInterface>PositionJointInterface</hardwareInterface>
    </joint>
    <!--Actuator-->
    <actuator name="motor1">
      <hardwareInterface>PositionJointInterface</hardwareInterface>
      <mechanicalReduction>1</mechanicalReduction>
    </actuator>
  </transmission>
  <transmission name="t1">
    <!--Type of Transmission-->
    <type>transmission_interace/SimpleTransmission</type>
    <!--Joint for transmission-->
    <joint name="elbow_pitch_joint">
      <hardwareInterface>PositionJointInterface</hardwareInterface>
    </joint>
    <!--Actuator-->
    <actuator name="motor1">
      <hardwareInterface>PositionJointInterface</hardwareInterface>
      <mechanicalReduction>1</mechanicalReduction>
    </actuator>
  </transmission>
  <transmission name="t1">
    <!--Type of Transmission-->
    <type>transmission_interace/SimpleTransmission</type>
    <!--Joint for transmission-->
    <joint name="wrist_roll_joint">
      <hardwareInterface>PositionJointInterface</hardwareInterface>
    </joint>
    <!--Actuator-->
    <actuator name="motor1">
      <hardwareInterface>PositionJointInterface</hardwareInterface>
      <mechanicalReduction>1</mechanicalReduction>
    </actuator>
  </transmission>
  <transmission name="t1">
    <!--Type of Transmission-->
    <type>transmission_interace/SimpleTransmission</type>
    <!--Joint for transmission-->
    <joint name="wrist_pitch_joint">
      <hardwareInterface>PositionJointInterface</hardwareInterface>
    </joint>
    <!--Actuator-->
    <actuator name="motor1">
      <hardwareInterface>PositionJointInterface</hardwareInterface>
      <mechanicalReduction>1</mechanicalReduction>
    </actuator>
  </transmission>
  <transmission name="t1">
    <!--Type of Transmission-->
    <type>transmission_interace/SimpleTransmission</type>
    <!--Joint for transmission-->
    <joint name="gripper_roll_joint">
      <hardwareInterface>PositionJointInterface</hardwareInterface>
    </joint>
    <!--Actuator-->
    <actuator name="motor1">
      <hardwareInterface>PositionJointInterface</hardwareInterface>
      <mechanicalReduction>1</mechanicalReduction>
    </actuator>
  </transmission>
  <transmission name="t1">
    <!--Type of Transmission-->
    <type>transmission_interace/SimpleTransmission</type>
    <!--Joint for transmission-->
    <joint name="finger_joint1">
      <hardwareInterface>PositionJointInterface</hardwareInterface>
    </joint>
    <!--Actuator-->
    <actuator name="motor1">
      <hardwareInterface>PositionJointInterface</hardwareInterface>
      <mechanicalReduction>1</mechanicalReduction>
    </actuator>
  </transmission>
  <transmission name="t1">
    <!--Type of Transmission-->
    <type>transmission_interace/SimpleTransmission</type>
    <!--Joint for transmission-->
    <joint name="finger_joint2">
      <hardwareInterface>PositionJointInterface</hardwareInterface>
    </joint>
    <!--Actuator-->
    <actuator name="motor1">
      <hardwareInterface>PositionJointInterface</hardwareInterface>
      <mechanicalReduction>1</mechanicalReduction>
    </actuator>
  </transmission>
  <!-- ros_control plugin -->
  <gazebo>
    <plugin filename="libgazebo_ros_control.so" name="gazebo_ros_control">
      <robotNamespace>/seven_dof_arm</robotNamespace>
    </plugin>
  </gazebo>
</robot>

